console.log('\nPromise ------------')
/** 
What ?
Â A Promise is technically a promise. Its a promise to do something when a task finishes
 Promises has three states: Pending, Resolved, Rejected

 Syntax is let promise = new Promise(function (resolve, reject){ ... })
 Resolve is called when the job finishes successfully.
 Reject is called when the job fails

 Promises object return new Promise constructor has these internal properties
 Promises contains state which initially is "pending" then moves to either resolved or reject
 Promises return another promise ...those can also resolve or reject. Hence promises can be chained together

 Note: The return on the promise is NOW the 'result' in the .then.
 Likewise: If the return on the promise is an error. Then "error" in the catch is the result

**/

// Ex1: Resolved
console.log('Ex1: Resolved')
let promise = await new Promise(async function (resolve, reject) {
  setTimeout(() => resolve('done'), 1000)
}).then((result) => {
  console.log('Ex1 Done')
})

// Ex2: Reject. Add a .catch to throw the error
let promise1 = await new Promise(function (resolve, reject) {
  // after 1 second signal that the job is finished with an error
  setTimeout(() => reject(new Error('Whoops!')), 1000)
}).catch((error) => {
  console.log('Ex1 error: ' + error + '\n\n')
})

// Then, catch
// syntax is: promise.then(function(result) {}, function(error) P{} )
// 1st argument of .then is run when the promise is resolved and receives the result
// 2nd argument of .then is a function when the promise is rejected and receives an error
console.log('Promise -> then ------------')

// Ex1: Resolve
let promise2 = new Promise(function (resolve, reject) {
  setTimeout(async () => resolve('done!'), 1000)
})

await promise2.then(
  (result) => console.log('Ex1 Promise then: ' + result), // shows "done!" after 1 second
  (error) => console(error) // doesn't run
)

// Ex2: Rejected
let promise3 = new Promise(function (resolve, reject) {
  setTimeout(async () => reject('error!'), 1000)
})

await promise3
  .then((error) => console.log(error))
  .catch((error) => {
    console.log('Ex2 Rejected error: ' + error)
  })

// Ex3: More streamlined solution
let promise4 = new Promise((resolve) => {
  setTimeout(async () => resolve('Doneeeee'), 1000)
})
await promise4.then((result) => console.log('Ex3 result: ' + result))

// catch
// Ex4: Will only catch errors
let promiseCatch = new Promise((resolve, reject) => {
  setTimeout(async () => reject(new Error('Whoops!')), 1000)
})

await promiseCatch.catch((error) => {
  console.log('Ex4 error statement: ' + error + '\n\n')
})

// Promises Chaining
// Chaining works since every call to .then returns a new promise hence we can chain promises together
console.log('Promises Chaining ------------')

// Ex1: Chaining
let promiseChaining = await new Promise(function (resolve, reject) {
  setTimeout(() => resolve(1), 1000)
})
  .then(function (result) {
    // result is the result of the Promise
    console.log('current Result: ' + result)
    return result * 2
  })
  .then(function (result) {
    console.log('current Result: ' + result)
    return result * 2
  })
  .then(function (result) {
    console.log('current Result: ' + result)
    return result * 2
  })

// Ex2: This is NOT Chaining
// The handler creates seperate handlers to one promise. They dont pass the value to each other and process it independently
console.log('This is NOT chaining')
let promiseChaining1 = new Promise(function (resolve, reject) {
  setTimeout(async () => resolve(1), 1000)
})

await promiseChaining1.then(function (result) {
  // result is the result of the Promise
  console.log('current Result: ' + result)
  return result * 2
})
await promiseChaining1.then(function (result) {
  // result is the result of the Promise
  console.log('current Result: ' + result)
  return result * 2
})
await promiseChaining1.then(function (result) {
  // result is the result of the Promise
  console.log('current Result: ' + result)
  return result * 2
})

// Ex3: Handlers will wait for previous handlers to finish before proceeding
// Returning promises allows us to build chains of asynchronous action
let promiseChaining2 = await new Promise(function (resolve, reject) {
  setTimeout(() => resolve(1), 1000)
})
  .then(function (result) {
    console.log('result: ' + result) // returns 1
    return new Promise((resolve, reject) => {
      setTimeout(() => resolve(result * 2), 1000)
    })
  })
  .then(function (result) {
    console.log('result: ' + result) // returns 2
    return new Promise((resolve, reject) => {
      setTimeout(() => resolve(result * 2), 1000)
    })
  })
  .then(function (result) {
    console.log('result: ' + result + '\n\n') // returns 4
  })

// Error Handling with promises
// When we reject a promise, we can attach a .catch() at the end of the .then() to catch the error message
console.log('Error Handling with Promises ------------')

// Ex1: Catch the error
let promiseChaining3 = new Promise(function (resolve, reject) {
  reject('Error whoops')
})

await promiseChaining3
  .then(function (result) {
    // result is the result of the Promise
    console.log('current Result: ' + result)
    return result * 2
  })
  .then(function (result) {
    console.log('current Result: ' + result)
    return result * 2
  })
  .catch(function (error) {
    // This will get triggered instead of the other two .then handlers
    console.log('error Message: ' + error + '\n\n')
  })

// Promise API
// There are 6 static methods in the Promise class
console.log('Promise API ------------')

// Promise.All
// Iterates through a list of promise and execute them in parallel and wait until all of them are ready
// Syntax: Promise.all()
// Note: If the iterable contains a non-Promise value, it will be ignored but still counted in the promise
// Promise.All rejects as a whole if any promise rejects. It implements AON
// Ex1
await Promise.all([
  new Promise((resolve, reject) => setTimeout(() => resolve(1), 3000)),
  new Promise((resolve, reject) => setTimeout(() => resolve(2), 2000)),
  new Promise((resolve, reject) => setTimeout(() => resolve(3), 1000)),
]).then((values) => {
  console.log('Ex1: ' + values) // Allows us to get the values from the Promises
})

// Ex2: Note this will throw a reject. Comment this out
await Promise.all([
  new Promise((resolve, reject) => setTimeout(() => resolve(1), 3000)),
  new Promise((resolve, reject) => setTimeout(() => reject(2), 2000)), // This should Faill All of the promises
  new Promise((resolve, reject) => setTimeout(() => resolve(3), 1000)),
])
  .then((values) => {
    console.log(values)
  })
  .catch((error) => {
    console.log('Ex2 error Message PromiseAll: ' + error + '\n\n')
  })

// Promise.allSettled
// Note - We use allSettled when one of the promises in the iterable can be rejected, we still keep moving forward
// In comparison .All(), it used AON. Either all of them pass or none of them do (reject)

console.log('Promise.allSettled ------------')

// Ex1
const promiseAllSettled1 = Promise.resolve(3)
const promiseAllSettled2 = new Promise(async (resolve, reject) => {
  setTimeout(reject, 100, 'foo')
})
const promiseAllSettledIterable = [promiseAllSettled1, promiseAllSettled2]
await Promise.allSettled(promiseAllSettledIterable).then((results) => {
  results.forEach((result) =>
    console.log('all Settled Ex: ' + result.status + '\n\n')
  )
})

/**
  Promise.race
  Similar to Promise.All but waits for first SETTLED promises in iterable to finish.
  Which ever one comes first will get returned.
  If Errors comes first, then that is returned
  Once the first promise is returned, all others are ignored
**/
console.log('Promise.race ------------')
// Ex1
await Promise.race([
  new Promise(async (resolve, reject) => setTimeout(() => resolve(1), 1000)), // This finishees first. Everything else is ignored
  new Promise(async (resolve, reject) =>
    setTimeout(async () => reject(new Error('Error found')), 2000)
  ),
  new Promise(async (resolve, reject) => setTimeout(() => resolve(3), 3000)),
]).then((value) => console.log('Promise.race Ex1 result: ' + value))

// Ex2
await Promise.race([
  new Promise(
    (resolve, reject) =>
      setTimeout(() => reject(new Error('Error found')), 1000) // This finishees first. Everything else is ignored
  ),
  new Promise((resolve, reject) => setTimeout(() => resolve(10), 1000)),
  new Promise((resolve, reject) => setTimeout(() => resolve(30), 3000)),
])
  .then((value) => console.log('result: ' + value))
  .catch((error) => {
    console.log('Promise.race Ex2 errror: ' + error + '\n\n')
  })

// Promise.any
// Similar to Promise.all but returns the first RESOLVED promise result ...Not the first Settled Promise
console.log('Promise.any ------------')

// Ex1
await Promise.any([
  new Promise(
    (resolve, reject) =>
      setTimeout(() => reject(new Error('Error found')), 1000) // Ignored since this is a reject
  ),
  new Promise(
    (resolve, reject) =>
      setTimeout(() => reject(new Error('Error found')), 2000) // Ignored since this is a reject
  ),
  new Promise((resolve, reject) => setTimeout(() => resolve(3), 3000)), // This is returned
]).then((value) => console.log('result: ' + value))

// Ex2: All promise rejected. Should see Aggregate Error
await Promise.any([
  new Promise((resolve, reject) =>
    setTimeout(() => reject(new Error('Ouch!')), 1000)
  ),
  new Promise((resolve, reject) =>
    setTimeout(() => reject(new Error('Error!')), 2000)
  ),
]).catch((error) => {
  console.log(error.constructor.name) // AggregateError
  console.log(error.errors[0]) // Error: Ouch!
  console.log(error.errors[1] + '\n\n') // Error: Error!
})

// Promise.resolve
// Resolves a given Promise
// Works exactly the same way as .resolve()
console.log('\nPromise.resolve & Promise.reject ------------')

// Ex1
const promiseResolve1 = Promise.resolve(1)
await promiseResolve1.then((value) => {
  console.log('Ex1 Value: ' + value)
})

// Ex2
const promiseResolve2 = Promise.reject(new Error('Error Found here'))
await promiseResolve2
  .then((value) => {
    console.log('Error: ' + value)
  })
  .catch((error) => {
    console.log('Ex2 error here: ' + error + '\n\n')
  })

// Microtask queue
// Promise handlers .then, .catch, .finally are always asynchrounous
// Even when promomises are resolved, lines BELOW .then/catch/finally  will still execute before these handlers
console.log('MicroTask Queue ------------ ')

// Ex:
let promiseQueue = Promise.resolve()
await promiseQueue.then(() => console.log('Promise Done')) // You will see line executed after 'Code Finished'
console.log('Code Finished') // You will see this one executed first

// Why ? Because of the MicroTask Queue
// Because then/catch/finally are put into queue, they are not executed.
// Only when JS engine becomes free from the current code, will the task take from the queue/

// How do we Set up a queue then ?
// By doing this instead:
let promiseQueue1 = Promise.resolve()
await promiseQueue1
  .then(() => console.log('Promise Done'))
  .then(() => console.log('Code Finished'))
